Traceback (most recent call last):
  File "/usr/lib/python3/dist-packages/urllib3/connection.py", line 159, in _new_conn
    (self._dns_host, self.port), self.timeout, **extra_kw)
  File "/usr/lib/python3/dist-packages/urllib3/util/connection.py", line 57, in create_connection
    for res in socket.getaddrinfo(host, port, family, socket.SOCK_STREAM):
  File "/usr/lib/python3.7/socket.py", line 748, in getaddrinfo
    for res in _socket.getaddrinfo(host, port, family, type, proto, flags):
socket.gaierror: [Errno -3] Temporary failure in name resolution

During handling of the above exception, another exception occurred:

Traceback (most recent call last):
  File "/usr/lib/python3/dist-packages/urllib3/connectionpool.py", line 600, in urlopen
    chunked=chunked)
  File "/usr/lib/python3/dist-packages/urllib3/connectionpool.py", line 343, in _make_request
    self._validate_conn(conn)
  File "/usr/lib/python3/dist-packages/urllib3/connectionpool.py", line 841, in _validate_conn
    conn.connect()
  File "/usr/lib/python3/dist-packages/urllib3/connection.py", line 301, in connect
    conn = self._new_conn()
  File "/usr/lib/python3/dist-packages/urllib3/connection.py", line 168, in _new_conn
    self, "Failed to establish a new connection: %s" % e)
urllib3.exceptions.NewConnectionError: <urllib3.connection.VerifiedHTTPSConnection object at 0x75983cf0>: Failed to establish a new connection: [Errno -3] Temporary failure in name resolution

During handling of the above exception, another exception occurred:

Traceback (most recent call last):
  File "/usr/lib/python3/dist-packages/requests/adapters.py", line 449, in send
    timeout=timeout
  File "/usr/lib/python3/dist-packages/urllib3/connectionpool.py", line 638, in urlopen
    _stacktrace=sys.exc_info()[2])
  File "/usr/lib/python3/dist-packages/urllib3/util/retry.py", line 398, in increment
    raise MaxRetryError(_pool, url, error or ResponseError(cause))
urllib3.exceptions.MaxRetryError: HTTPSConnectionPool(host='breatheazy-api.herokuapp.com', port=443): Max retries exceeded with url: /mongo/sensor (Caused by NewConnectionError('<urllib3.connection.VerifiedHTTPSConnection object at 0x75983cf0>: Failed to establish a new connection: [Errno -3] Temporary failure in name resolution'))

During handling of the above exception, another exception occurred:

Traceback (most recent call last):
  File "sensor.py", line 25, in <module>
    schedule.run_pending()
  File "/home/pi/.local/lib/python3.7/site-packages/schedule/__init__.py", line 592, in run_pending
    default_scheduler.run_pending()
  File "/home/pi/.local/lib/python3.7/site-packages/schedule/__init__.py", line 94, in run_pending
    self._run_job(job)
  File "/home/pi/.local/lib/python3.7/site-packages/schedule/__init__.py", line 147, in _run_job
    ret = job.run()
  File "/home/pi/.local/lib/python3.7/site-packages/schedule/__init__.py", line 491, in run
    ret = self.job_func()
  File "sensor.py", line 17, in recordData
    addSensor(username, str(pmt_2_5),str(pmt_10), temp, humidity, str(ct))
  File "/home/pi/Documents/SJSU/Spring2021/py-sds011/api.py", line 41, in addSensor
    sensorData = requests.post(addSensorRoute, data=json.dumps(payload), headers = headers)
  File "/usr/lib/python3/dist-packages/requests/api.py", line 116, in post
    return request('post', url, data=data, json=json, **kwargs)
  File "/usr/lib/python3/dist-packages/requests/api.py", line 60, in request
    return session.request(method=method, url=url, **kwargs)
  File "/usr/lib/python3/dist-packages/requests/sessions.py", line 533, in request
    resp = self.send(prep, **send_kwargs)
  File "/usr/lib/python3/dist-packages/requests/sessions.py", line 646, in send
    r = adapter.send(request, **kwargs)
  File "/usr/lib/python3/dist-packages/requests/adapters.py", line 516, in send
    raise ConnectionError(e, request=request)
requests.exceptions.ConnectionError: HTTPSConnectionPool(host='breatheazy-api.herokuapp.com', port=443): Max retries exceeded with url: /mongo/sensor (Caused by NewConnectionError('<urllib3.connection.VerifiedHTTPSConnection object at 0x75983cf0>: Failed to establish a new connection: [Errno -3] Temporary failure in name resolution'))
